Workbook
Name REF_unit_code: 'Master_Unit'!$A$2:$A$4
Name REF_product_code: 'Master_Produk'!$A$2:$A$3
Name REF_area_code: 'Master_Area'!$A$2:$A$3
Name REF_owner_team_code: 'Master_Tim'!$A$2:$A$4
Name REF_indicator_code: 'Master_Indikator'!$A$2:$A$9

Sheet BACA_DULU
A1: bagian | B1: petunjuk
A2: Peringatan | B2: SELURUH DATA DAN TARGET FIKTIF. Bukan data production, rekomendasi final atau bukti kausal.
A3: Topik | B3: Survei anonim 1-5, respons valid/tidak lengkap, penyebut CSAT dan rekap produk.
A4: Batas interpretasi | B4: CSAT memakai skor 4/5 dibagi respons valid, bukan NPS. Sampel kecil opt-in tidak memberi klaim representatif atau confidence statistik otomatis.
A5: Impor Google Sheets | B5: Upload Excel ke Drive lalu buka/konversi sebagai Google Sheets. Periksa formula, tanggal dan jumlah baris sebelum onboarding.
A6: Waktu | B6: Tanggal disimpan sebagai teks ISO yyyy-mm-dd: pilih date, parse_date_id, format TEXT, pola %Y-%m-%d. Timestamp teks ISO ber-offset: timestamptz.
A7: Master | B7: Master bersama identik pada beberapa file: muat sekali ke Registry master, lalu gunakan kembali binding. Jangan menggandakan registry master yang sama.
A8: Rekap | B8: Rekap/rataan/rasio utama ditautkan ke raw lewat formula dan cache. Recalculate setelah edit/impor, periksa jumlah baris, penyebut dan master. CSV berisi hasil numerik, bukan formula.
A9: Klasifikasi | B9: Master_* = MASTER. Tab data/rekap/Action_Plan = NON_MASTER. BACA_DULU, Kamus_Data, Rencana_ETL = petunjuk, Dikecualikan dari ETL.
A10: Action plan | B10: Baseline diambil dari record sumber; cause_status UNVERIFIED, follow-up kosong/NOT_EVALUATED. Verifikasi bukti dan pilih target bisnis sebelum tindakan.
A11: Load | B11: Contoh memakai key unik dan saran UPSERT. Review grain, reference binding, tipe, DQ, metrik, access dan rilis sebelum deploy. Jangan upload contoh ke sumber production yang aktif.

Sheet Kamus_Data
A1: sheet | B1: column | C1: type | D1: nullable | E1: business_key | F1: meaning | G1: example
A2: Master_Unit | B2: unit_code | C2: text | D2: FALSE | E2: TRUE | F2: Identitas stabil sesuai grain. | G2: UNIT-CS
A3: Master_Unit | B3: unit_label | C3: text | D3: FALSE | E3: FALSE | F3: Kode/label/atribut sesuai nama kolom dan grain; lihat Rencana_ETL serta definisi metrik. Jangan menjumlahkan rasio atau satuan berbeda. | G3: Layanan Pelanggan
A4: Master_Unit | B4: is_active | C4: boolean | D4: FALSE | E4: FALSE | F4: Kode/label/atribut sesuai nama kolom dan grain; lihat Rencana_ETL serta definisi metrik. Jangan menjumlahkan rasio atau satuan berbeda. | G4: True
A5: Master_Produk | B5: product_code | C5: text | D5: FALSE | E5: TRUE | F5: Identitas stabil sesuai grain. | G5: PROD-MILK
A6: Master_Produk | B6: product_label | C6: text | D6: FALSE | E6: FALSE | F6: Kode/label/atribut sesuai nama kolom dan grain; lihat Rencana_ETL serta definisi metrik. Jangan menjumlahkan rasio atau satuan berbeda. | G6: Susu Contoh Plain
A7: Master_Produk | B7: product_group | C7: text | D7: FALSE | E7: FALSE | F7: Kode/label/atribut sesuai nama kolom dan grain; lihat Rencana_ETL serta definisi metrik. Jangan menjumlahkan rasio atau satuan berbeda. | G7: DAIRY
A8: Master_Produk | B8: is_active | C8: boolean | D8: FALSE | E8: FALSE | F8: Kode/label/atribut sesuai nama kolom dan grain; lihat Rencana_ETL serta definisi metrik. Jangan menjumlahkan rasio atau satuan berbeda. | G8: True
A9: Master_Area | B9: area_code | C9: text | D9: FALSE | E9: TRUE | F9: Identitas stabil sesuai grain. | G9: AREA-A
A10: Master_Area | B10: area_label | C10: text | D10: FALSE | E10: FALSE | F10: Kode/label/atribut sesuai nama kolom dan grain; lihat Rencana_ETL serta definisi metrik. Jangan menjumlahkan rasio atau satuan berbeda. | G10: Wilayah Contoh A
A11: Master_Area | B11: is_active | C11: boolean | D11: FALSE | E11: FALSE | F11: Kode/label/atribut sesuai nama kolom dan grain; lihat Rencana_ETL serta definisi metrik. Jangan menjumlahkan rasio atau satuan berbeda. | G11: True
A12: Master_Tim | B12: owner_team_code | C12: text | D12: FALSE | E12: TRUE | F12: Identitas stabil sesuai grain. | G12: TEAM-CS
A13: Master_Tim | B13: team_label | C13: text | D13: FALSE | E13: FALSE | F13: Kode/label/atribut sesuai nama kolom dan grain; lihat Rencana_ETL serta definisi metrik. Jangan menjumlahkan rasio atau satuan berbeda. | G13: Tim Layanan
... A82: Action_Plan | B82: collected_at | C82: timestamptz | D82: FALSE | E82: FALSE | F82: Waktu pengambilan, bukan periode bisnis. | G82: 2026-02-02T09:00:00+07:00

Sheet Rencana_ETL
A1: sheet | B1: classification | C1: grain | D1: business_key | E1: load | F1: metrics | G1: notes
A2: Master_Unit | B2: MASTER | C2: satu baris per unit | D2: unit_code | E2: Registry master | F2: Review definisi sebelum menambahkan metrik
A3: Master_Produk | B3: MASTER | C3: satu baris per produk | D3: product_code | E3: Registry master | F3: Review definisi sebelum menambahkan metrik
A4: Master_Area | B4: MASTER | C4: satu baris per area | D4: area_code | E4: Registry master | F4: Review definisi sebelum menambahkan metrik
A5: Master_Tim | B5: MASTER | C5: satu baris per tim penanggung jawab | D5: owner_team_code | E5: Registry master | F5: Review definisi sebelum menambahkan metrik
A6: Master_Indikator | B6: MASTER | C6: satu baris per indikator dengan definisi dan satuan | D6: indicator_code | E6: Registry master | F6: Review definisi sebelum menambahkan metrik
A7: Survey_Data | B7: NON_MASTER | C7: satu baris per respons anonim produk metode survei | D7: response_id | E7: UPSERT | F7: valid_response_count:sum [RESPONSE]; satisfied_count:sum [RESPONSE] | G7: CSAT produk berdasarkan product_score >=4; bukan NPS. Jangan mencampur versi pertanyaan atau menganggap sampel opt-in mewakili seluruh pelanggan.
A8: CSAT_Rekap | B8: NON_MASTER | C8: satu baris per produk area versi survei periode | D8: csat_summary_id | E8: UPSERT | F8: valid_response_count:sum [RESPONSE]; satisfied_count:sum [RESPONSE] | G8: Sampel kecil dan opt-in: tidak ada margin of error atau klaim representatif otomatis. Rekap memakai respons valid dan formula dari raw; invited_count harus diperbarui dari log undangan yang sah.
A9: Action_Plan | B9: NON_MASTER | C9: satu baris per tindakan yang merujuk record temuan | D9: action_id | E9: UPSERT | F9: Review definisi sebelum menambahkan metrik | G9: Baseline dibekukan sesuai periode bukti; hipotesis belum terverifikasi. Nilai follow-up kosong berarti belum dievaluasi, bukan nol.

Sheet Master_Unit
A1: unit_code | B1: unit_label | C1: is_active
A2: UNIT-CS | B2: Layanan Pelanggan | C2: TRUE
A3: UNIT-MKT | B3: Marketing | C3: TRUE
A4: UNIT-OPS | B4: Operasional | C4: TRUE

Sheet Master_Produk
A1: product_code | B1: product_label | C1: product_group | D1: is_active
A2: PROD-MILK | B2: Susu Contoh Plain | C2: DAIRY | D2: TRUE
A3: PROD-FEED | B3: Pakan Contoh | C3: FEED | D3: TRUE

Sheet Master_Area
A1: area_code | B1: area_label | C1: is_active
A2: AREA-A | B2: Wilayah Contoh A | C2: TRUE
A3: AREA-B | B3: Wilayah Contoh B | C3: TRUE

Sheet Master_Tim
A1: owner_team_code | B1: team_label | C1: unit_code
A2: TEAM-CS | B2: Tim Layanan | C2: UNIT-CS
A3: TEAM-MKT | B3: Tim Marketing | C3: UNIT-MKT
A4: TEAM-OPS | B4: Tim Operasional | C4: UNIT-OPS

Sheet Master_Indikator
A1: indicator_code | B1: indicator_label | C1: measurement_unit | D1: direction | E1: aggregation | F1: definition
A2: REVENUE | B2: Pendapatan tercatat | C2: IDR | D2: HIGHER_IS_BETTER | E2: SUM | F2: Jumlah pendapatan tercatat pada periode.
A3: RESOLVED | B3: Kasus selesai | C3: CASE | D3: HIGHER_IS_BETTER | E3: SUM | F3: Jumlah kasus unik selesai pada periode.
A4: RESPONSE_HOURS | B4: Jam respons awal | C4: HOUR | D4: LOWER_IS_BETTER | E4: AVG | F4: Rata-rata jam respons dari sampel yang dicatat.
A5: SATISFACTION | B5: Skor kepuasan | C5: SCORE_1_5 | D5: HIGHER_IS_BETTER | E5: AVG | F5: Rating sampel 1 sampai 5, bukan CSAT/NPS.
A6: SLA_BREACH | B6: Rasio pelanggaran SLA | C6: RATIO | D6: LOWER_IS_BETTER | E6: RECOMPUTE_RATIO | F6: Keluhan melewati SLA / keluhan cohort periode.
A7: COST_QUALIFIED_LEAD | B7: Biaya per qualified lead | C7: IDR_PER_LEAD | D7: LOWER_IS_BETTER | E7: RECOMPUTE_RATIO | F7: Spend / qualified leads yang teratribusi dan terdeduplikasi.
A8: PRODUCT_CSAT | B8: CSAT produk | C8: RATIO | D8: HIGHER_IS_BETTER | E8: RECOMPUTE_RATIO | F8: Skor produk 4/5 dibagi respons valid pada versi survei yang sama.
A9: SERVICE_SCORE | B9: Skor layanan | C9: SCORE_1_5 | D9: HIGHER_IS_BETTER | E9: AVG | F9: Rataan skor layanan dalam metode/sampel yang sebanding.

Sheet Survey_Data
A1: response_id | B1: respondent_code | C1: unit_code | D1: product_code | E1: area_code | F1: survey_version | G1: surveyed_at | H1: product_score | I1: service_score | J1: value_score | K1: is_valid_response | L1: excluded_reason | M1: valid_response_count | N1: satisfied_count | O1: sampling_method | P1: period_start | Q1: period_end | R1: collected_at | S1: data_as_of_at
A2: SUR-1-PROD-MILK-00 | B2: ANON-1-PROD-MILK-00 | C2: UNIT-CS | D2: PROD-MILK | E2: AREA-A | F2: CSAT-5-V1 | G2: 2026-01-10T09:00:00+07:00 | H2: 2 | I2: 4 | J2: 3 | K2: TRUE | M2: 1 | N2: 0 | O2: OPT_IN_SIMULATED | P2: 2026-01-01 | Q2: 2026-01-31 | R2: 2026-03-03T09:00:00+07:00 | S2: 2026-03-03T09:00:00+07:00
A3: SUR-1-PROD-MILK-01 | B3: ANON-1-PROD-MILK-01 | C3: UNIT-CS | D3: PROD-MILK | E3: AREA-A | F3: CSAT-5-V1 | G3: 2026-01-11T09:00:00+07:00 | H3: 3 | I3: 4 | J3: 3 | K3: TRUE | M3: 1 | N3: 0 | O3: OPT_IN_SIMULATED | P3: 2026-01-01 | Q3: 2026-01-31 | R3: 2026-03-03T09:00:00+07:00 | S3: 2026-03-03T09:00:00+07:00
A4: SUR-1-PROD-MILK-02 | B4: ANON-1-PROD-MILK-02 | C4: UNIT-CS | D4: PROD-MILK | E4: AREA-A | F4: CSAT-5-V1 | G4: 2026-01-12T09:00:00+07:00 | H4: 3 | I4: 4 | J4: 3 | K4: TRUE | M4: 1 | N4: 0 | O4: OPT_IN_SIMULATED | P4: 2026-01-01 | Q4: 2026-01-31 | R4: 2026-03-03T09:00:00+07:00 | S4: 2026-03-03T09:00:00+07:00
A5: SUR-1-PROD-MILK-03 | B5: ANON-1-PROD-MILK-03 | C5: UNIT-CS | D5: PROD-MILK | E5: AREA-A | F5: CSAT-5-V1 | G5: 2026-01-13T09:00:00+07:00 | H5: 4 | I5: 4 | J5: 3 | K5: TRUE | M5: 1 | N5: 1 | O5: OPT_IN_SIMULATED | P5: 2026-01-01 | Q5: 2026-01-31 | R5: 2026-03-03T09:00:00+07:00 | S5: 2026-03-03T09:00:00+07:00
A6: SUR-1-PROD-MILK-04 | B6: ANON-1-PROD-MILK-04 | C6: UNIT-CS | D6: PROD-MILK | E6: AREA-A | F6: CSAT-5-V1 | G6: 2026-01-14T09:00:00+07:00 | H6: 4 | I6: 4 | J6: 3 | K6: TRUE | M6: 1 | N6: 1 | O6: OPT_IN_SIMULATED | P6: 2026-01-01 | Q6: 2026-01-31 | R6: 2026-03-03T09:00:00+07:00 | S6: 2026-03-03T09:00:00+07:00
A7: SUR-1-PROD-MILK-05 | B7: ANON-1-PROD-MILK-05 | C7: UNIT-CS | D7: PROD-MILK | E7: AREA-A | F7: CSAT-5-V1 | G7: 2026-01-15T09:00:00+07:00 | H7: 5 | I7: 4 | J7: 3 | K7: TRUE | M7: 1 | N7: 1 | O7: OPT_IN_SIMULATED | P7: 2026-01-01 | Q7: 2026-01-31 | R7: 2026-03-03T09:00:00+07:00 | S7: 2026-03-03T09:00:00+07:00
A8: SUR-1-PROD-MILK-06 | B8: ANON-1-PROD-MILK-06 | C8: UNIT-CS | D8: PROD-MILK | E8: AREA-A | F8: CSAT-5-V1 | G8: 2026-01-16T09:00:00+07:00 | H8: 2 | I8: 4 | J8: 3 | K8: TRUE | M8: 1 | N8: 0 | O8: OPT_IN_SIMULATED | P8: 2026-01-01 | Q8: 2026-01-31 | R8: 2026-03-03T09:00:00+07:00 | S8: 2026-03-03T09:00:00+07:00
A9: SUR-1-PROD-MILK-07 | B9: ANON-1-PROD-MILK-07 | C9: UNIT-CS | D9: PROD-MILK | E9: AREA-A | F9: CSAT-5-V1 | G9: 2026-01-17T09:00:00+07:00 | H9: 3 | I9: 4 | J9: 3 | K9: TRUE | M9: 1 | N9: 0 | O9: OPT_IN_SIMULATED | P9: 2026-01-01 | Q9: 2026-01-31 | R9: 2026-03-03T09:00:00+07:00 | S9: 2026-03-03T09:00:00+07:00
A10: SUR-1-PROD-MILK-08 | B10: ANON-1-PROD-MILK-08 | C10: UNIT-CS | D10: PROD-MILK | E10: AREA-A | F10: CSAT-5-V1 | G10: 2026-01-18T09:00:00+07:00 | H10: 3 | I10: 4 | J10: 3 | K10: TRUE | M10: 1 | N10: 0 | O10: OPT_IN_SIMULATED | P10: 2026-01-01 | Q10: 2026-01-31 | R10: 2026-03-03T09:00:00+07:00 | S10: 2026-03-03T09:00:00+07:00
A11: SUR-1-PROD-MILK-09 | B11: ANON-1-PROD-MILK-09 | C11: UNIT-CS | D11: PROD-MILK | E11: AREA-A | F11: CSAT-5-V1 | G11: 2026-01-19T09:00:00+07:00 | H11: 4 | I11: 4 | J11: 3 | K11: TRUE | M11: 1 | N11: 1 | O11: OPT_IN_SIMULATED | P11: 2026-01-01 | Q11: 2026-01-31 | R11: 2026-03-03T09:00:00+07:00 | S11: 2026-03-03T09:00:00+07:00
A12: SUR-1-PROD-MILK-10 | B12: ANON-1-PROD-MILK-10 | C12: UNIT-CS | D12: PROD-MILK | E12: AREA-A | F12: CSAT-5-V1 | G12: 2026-01-20T09:00:00+07:00 | H12: 4 | I12: 4 | J12: 3 | K12: TRUE | M12: 1 | N12: 1 | O12: OPT_IN_SIMULATED | P12: 2026-01-01 | Q12: 2026-01-31 | R12: 2026-03-03T09:00:00+07:00 | S12: 2026-03-03T09:00:00+07:00
A13: SUR-1-PROD-MILK-11 | B13: ANON-1-PROD-MILK-11 | C13: UNIT-CS | D13: PROD-MILK | E13: AREA-A | F13: CSAT-5-V1 | G13: 2026-01-21T09:00:00+07:00 | K13: FALSE | L13: INCOMPLETE | M13: 0 | N13: 0 | O13: OPT_IN_SIMULATED | P13: 2026-01-01 | Q13: 2026-01-31 | R13: 2026-03-03T09:00:00+07:00 | S13: 2026-03-03T09:00:00+07:00
A14: SUR-1-PROD-FEED-00 | B14: ANON-1-PROD-FEED-00 | C14: UNIT-CS | D14: PROD-FEED | E14: AREA-A | F14: CSAT-5-V1 | G14: 2026-01-10T09:00:00+07:00 | H14: 2 | I14: 4 | J14: 3 | K14: TRUE | M14: 1 | N14: 0 | O14: OPT_IN_SIMULATED | P14: 2026-01-01 | Q14: 2026-01-31 | R14: 2026-03-03T09:00:00+07:00 | S14: 2026-03-03T09:00:00+07:00
A15: SUR-1-PROD-FEED-01 | B15: ANON-1-PROD-FEED-01 | C15: UNIT-CS | D15: PROD-FEED | E15: AREA-A | F15: CSAT-5-V1 | G15: 2026-01-11T09:00:00+07:00 | H15: 3 | I15: 4 | J15: 3 | K15: TRUE | M15: 1 | N15: 0 | O15: OPT_IN_SIMULATED | P15: 2026-01-01 | Q15: 2026-01-31 | R15: 2026-03-03T09:00:00+07:00 | S15: 2026-03-03T09:00:00+07:00
A16: SUR-1-PROD-FEED-02 | B16: ANON-1-PROD-FEED-02 | C16: UNIT-CS | D16: PROD-FEED | E16: AREA-A | F16: CSAT-5-V1 | G16: 2026-01-12T09:00:00+07:00 | H16: 3 | I16: 4 | J16: 3 | K16: TRUE | M16: 1 | N16: 0 | O16: OPT_IN_SIMULATED | P16: 2026-01-01 | Q16: 2026-01-31 | R16: 2026-03-03T09:00:00+07:00 | S16: 2026-03-03T09:00:00+07:00
A17: SUR-1-PROD-FEED-03 | B17: ANON-1-PROD-FEED-03 | C17: UNIT-CS | D17: PROD-FEED | E17: AREA-A | F17: CSAT-5-V1 | G17: 2026-01-13T09:00:00+07:00 | H17: 4 | I17: 4 | J17: 3 | K17: TRUE | M17: 1 | N17: 1 | O17: OPT_IN_SIMULATED | P17: 2026-01-01 | Q17: 2026-01-31 | R17: 2026-03-03T09:00:00+07:00 | S17: 2026-03-03T09:00:00+07:00
A18: SUR-1-PROD-FEED-04 | B18: ANON-1-PROD-FEED-04 | C18: UNIT-CS | D18: PROD-FEED | E18: AREA-A | F18: CSAT-5-V1 | G18: 2026-01-14T09:00:00+07:00 | H18: 4 | I18: 4 | J18: 3 | K18: TRUE | M18: 1 | N18: 1 | O18: OPT_IN_SIMULATED | P18: 2026-01-01 | Q18: 2026-01-31 | R18: 2026-03-03T09:00:00+07:00 | S18: 2026-03-03T09:00:00+07:00
A19: SUR-1-PROD-FEED-05 | B19: ANON-1-PROD-FEED-05 | C19: UNIT-CS | D19: PROD-FEED | E19: AREA-A | F19: CSAT-5-V1 | G19: 2026-01-15T09:00:00+07:00 | H19: 5 | I19: 4 | J19: 3 | K19: TRUE | M19: 1 | N19: 1 | O19: OPT_IN_SIMULATED | P19: 2026-01-01 | Q19: 2026-01-31 | R19: 2026-03-03T09:00:00+07:00 | S19: 2026-03-03T09:00:00+07:00
A20: SUR-1-PROD-FEED-06 | B20: ANON-1-PROD-FEED-06 | C20: UNIT-CS | D20: PROD-FEED | E20: AREA-A | F20: CSAT-5-V1 | G20: 2026-01-16T09:00:00+07:00 | H20: 2 | I20: 4 | J20: 3 | K20: TRUE | M20: 1 | N20: 0 | O20: OPT_IN_SIMULATED | P20: 2026-01-01 | Q20: 2026-01-31 | R20: 2026-03-03T09:00:00+07:00 | S20: 2026-03-03T09:00:00+07:00
A21: SUR-1-PROD-FEED-07 | B21: ANON-1-PROD-FEED-07 | C21: UNIT-CS | D21: PROD-FEED | E21: AREA-A | F21: CSAT-5-V1 | G21: 2026-01-17T09:00:00+07:00 | H21: 3 | I21: 4 | J21: 3 | K21: TRUE | M21: 1 | N21: 0 | O21: OPT_IN_SIMULATED | P21: 2026-01-01 | Q21: 2026-01-31 | R21: 2026-03-03T09:00:00+07:00 | S21: 2026-03-03T09:00:00+07:00
A22: SUR-1-PROD-FEED-08 | B22: ANON-1-PROD-FEED-08 | C22: UNIT-CS | D22: PROD-FEED | E22: AREA-A | F22: CSAT-5-V1 | G22: 2026-01-18T09:00:00+07:00 | H22: 3 | I22: 4 | J22: 3 | K22: TRUE | M22: 1 | N22: 0 | O22: OPT_IN_SIMULATED | P22: 2026-01-01 | Q22: 2026-01-31 | R22: 2026-03-03T09:00:00+07:00 | S22: 2026-03-03T09:00:00+07:00
A23: SUR-1-PROD-FEED-09 | B23: ANON-1-PROD-FEED-09 | C23: UNIT-CS | D23: PROD-FEED | E23: AREA-A | F23: CSAT-5-V1 | G23: 2026-01-19T09:00:00+07:00 | H23: 4 | I23: 4 | J23: 3 | K23: TRUE | M23: 1 | N23: 1 | O23: OPT_IN_SIMULATED | P23: 2026-01-01 | Q23: 2026-01-31 | R23: 2026-03-03T09:00:00+07:00 | S23: 2026-03-03T09:00:00+07:00
A24: SUR-1-PROD-FEED-10 | B24: ANON-1-PROD-FEED-10 | C24: UNIT-CS | D24: PROD-FEED | E24: AREA-A | F24: CSAT-5-V1 | G24: 2026-01-20T09:00:00+07:00 | H24: 4 | I24: 4 | J24: 3 | K24: TRUE | M24: 1 | N24: 1 | O24: OPT_IN_SIMULATED | P24: 2026-01-01 | Q24: 2026-01-31 | R24: 2026-03-03T09:00:00+07:00 | S24: 2026-03-03T09:00:00+07:00
A25: SUR-1-PROD-FEED-11 | B25: ANON-1-PROD-FEED-11 | C25: UNIT-CS | D25: PROD-FEED | E25: AREA-A | F25: CSAT-5-V1 | G25: 2026-01-21T09:00:00+07:00 | K25: FALSE | L25: INCOMPLETE | M25: 0 | N25: 0 | O25: OPT_IN_SIMULATED | P25: 2026-01-01 | Q25: 2026-01-31 | R25: 2026-03-03T09:00:00+07:00 | S25: 2026-03-03T09:00:00+07:00
A26: SUR-2-PROD-MILK-00 | B26: ANON-2-PROD-MILK-00 | C26: UNIT-CS | D26: PROD-MILK | E26: AREA-A | F26: CSAT-5-V1 | G26: 2026-02-10T09:00:00+07:00 | H26: 3 | I26: 4 | J26: 3 | K26: TRUE | M26: 1 | N26: 0 | O26: OPT_IN_SIMULATED | P26: 2026-02-01 | Q26: 2026-02-28 | R26: 2026-03-03T09:00:00+07:00 | S26: 2026-03-03T09:00:00+07:00
A27: SUR-2-PROD-MILK-01 | B27: ANON-2-PROD-MILK-01 | C27: UNIT-CS | D27: PROD-MILK | E27: AREA-A | F27: CSAT-5-V1 | G27: 2026-02-11T09:00:00+07:00 | H27: 4 | I27: 4 | J27: 3 | K27: TRUE | M27: 1 | N27: 1 | O27: OPT_IN_SIMULATED | P27: 2026-02-01 | Q27: 2026-02-28 | R27: 2026-03-03T09:00:00+07:00 | S27: 2026-03-03T09:00:00+07:00
A28: SUR-2-PROD-MILK-02 | B28: ANON-2-PROD-MILK-02 | C28: UNIT-CS | D28: PROD-MILK | E28: AREA-A | F28: CSAT-5-V1 | G28: 2026-02-12T09:00:00+07:00 | H28: 4 | I28: 4 | J28: 3 | K28: TRUE | M28: 1 | N28: 1 | O28: OPT_IN_SIMULATED | P28: 2026-02-01 | Q28: 2026-02-28 | R28: 2026-03-03T09:00:00+07:00 | S28: 2026-03-03T09:00:00+07:00
A29: SUR-2-PROD-MILK-03 | B29: ANON-2-PROD-MILK-03 | C29: UNIT-CS | D29: PROD-MILK | E29: AREA-A | F29: CSAT-5-V1 | G29: 2026-02-13T09:00:00+07:00 | H29: 4 | I29: 4 | J29: 3 | K29: TRUE | M29: 1 | N29: 1 | O29: OPT_IN_SIMULATED | P29: 2026-02-01 | Q29: 2026-02-28 | R29: 2026-03-03T09:00:00+07:00 | S29: 2026-03-03T09:00:00+07:00
A30: SUR-2-PROD-MILK-04 | B30: ANON-2-PROD-MILK-04 | C30: UNIT-CS | D30: PROD-MILK | E30: AREA-A | F30: CSAT-5-V1 | G30: 2026-02-14T09:00:00+07:00 | H30: 5 | I30: 4 | J30: 3 | K30: TRUE | M30: 1 | N30: 1 | O30: OPT_IN_SIMULATED | P30: 2026-02-01 | Q30: 2026-02-28 | R30: 2026-03-03T09:00:00+07:00 | S30: 2026-03-03T09:00:00+07:00
A31: SUR-2-PROD-MILK-05 | B31: ANON-2-PROD-MILK-05 | C31: UNIT-CS | D31: PROD-MILK | E31: AREA-A | F31: CSAT-5-V1 | G31: 2026-02-15T09:00:00+07:00 | H31: 5 | I31: 4 | J31: 3 | K31: TRUE | M31: 1 | N31: 1 | O31: OPT_IN_SIMULATED | P31: 2026-02-01 | Q31: 2026-02-28 | R31: 2026-03-03T09:00:00+07:00 | S31: 2026-03-03T09:00:00+07:00
A32: SUR-2-PROD-MILK-06 | B32: ANON-2-PROD-MILK-06 | C32: UNIT-CS | D32: PROD-MILK | E32: AREA-A | F32: CSAT-5-V1 | G32: 2026-02-16T09:00:00+07:00 | H32: 3 | I32: 4 | J32: 3 | K32: TRUE | M32: 1 | N32: 0 | O32: OPT_IN_SIMULATED | P32: 2026-02-01 | Q32: 2026-02-28 | R32: 2026-03-03T09:00:00+07:00 | S32: 2026-03-03T09:00:00+07:00
A33: SUR-2-PROD-MILK-07 | B33: ANON-2-PROD-MILK-07 | C33: UNIT-CS | D33: PROD-MILK | E33: AREA-A | F33: CSAT-5-V1 | G33: 2026-02-17T09:00:00+07:00 | H33: 4 | I33: 4 | J33: 3 | K33: TRUE | M33: 1 | N33: 1 | O33: OPT_IN_SIMULATED | P33: 2026-02-01 | Q33: 2026-02-28 | R33: 2026-03-03T09:00:00+07:00 | S33: 2026-03-03T09:00:00+07:00
A34: SUR-2-PROD-MILK-08 | B34: ANON-2-PROD-MILK-08 | C34: UNIT-CS | D34: PROD-MILK | E34: AREA-A | F34: CSAT-5-V1 | G34: 2026-02-18T09:00:00+07:00 | H34: 4 | I34: 4 | J34: 3 | K34: TRUE | M34: 1 | N34: 1 | O34: OPT_IN_SIMULATED | P34: 2026-02-01 | Q34: 2026-02-28 | R34: 2026-03-03T09:00:00+07:00 | S34: 2026-03-03T09:00:00+07:00
A35: SUR-2-PROD-MILK-09 | B35: ANON-2-PROD-MILK-09 | C35: UNIT-CS | D35: PROD-MILK | E35: AREA-A | F35: CSAT-5-V1 | G35: 2026-02-19T09:00:00+07:00 | H35: 4 | I35: 4 | J35: 3 | K35: TRUE | M35: 1 | N35: 1 | O35: OPT_IN_SIMULATED | P35: 2026-02-01 | Q35: 2026-02-28 | R35: 2026-03-03T09:00:00+07:00 | S35: 2026-03-03T09:00:00+07:00
A36: SUR-2-PROD-MILK-10 | B36: ANON-2-PROD-MILK-10 | C36: UNIT-CS | D36: PROD-MILK | E36: AREA-A | F36: CSAT-5-V1 | G36: 2026-02-20T09:00:00+07:00 | H36: 5 | I36: 4 | J36: 3 | K36: TRUE | M36: 1 | N36: 1 | O36: OPT_IN_SIMULATED | P36: 2026-02-01 | Q36: 2026-02-28 | R36: 2026-03-03T09:00:00+07:00 | S36: 2026-03-03T09:00:00+07:00
A37: SUR-2-PROD-MILK-11 | B37: ANON-2-PROD-MILK-11 | C37: UNIT-CS | D37: PROD-MILK | E37: AREA-A | F37: CSAT-5-V1 | G37: 2026-02-21T09:00:00+07:00 | K37: FALSE | L37: INCOMPLETE | M37: 0 | N37: 0 | O37: OPT_IN_SIMULATED | P37: 2026-02-01 | Q37: 2026-02-28 | R37: 2026-03-03T09:00:00+07:00 | S37: 2026-03-03T09:00:00+07:00
A38: SUR-2-PROD-FEED-00 | B38: ANON-2-PROD-FEED-00 | C38: UNIT-CS | D38: PROD-FEED | E38: AREA-A | F38: CSAT-5-V1 | G38: 2026-02-10T09:00:00+07:00 | H38: 3 | I38: 4 | J38: 3 | K38: TRUE | M38: 1 | N38: 0 | O38: OPT_IN_SIMULATED | P38: 2026-02-01 | Q38: 2026-02-28 | R38: 2026-03-03T09:00:00+07:00 | S38: 2026-03-03T09:00:00+07:00
A39: SUR-2-PROD-FEED-01 | B39: ANON-2-PROD-FEED-01 | C39: UNIT-CS | D39: PROD-FEED | E39: AREA-A | F39: CSAT-5-V1 | G39: 2026-02-11T09:00:00+07:00 | H39: 4 | I39: 4 | J39: 3 | K39: TRUE | M39: 1 | N39: 1 | O39: OPT_IN_SIMULATED | P39: 2026-02-01 | Q39: 2026-02-28 | R39: 2026-03-03T09:00:00+07:00 | S39: 2026-03-03T09:00:00+07:00
A40: SUR-2-PROD-FEED-02 | B40: ANON-2-PROD-FEED-02 | C40: UNIT-CS | D40: PROD-FEED | E40: AREA-A | F40: CSAT-5-V1 | G40: 2026-02-12T09:00:00+07:00 | H40: 4 | I40: 4 | J40: 3 | K40: TRUE | M40: 1 | N40: 1 | O40: OPT_IN_SIMULATED | P40: 2026-02-01 | Q40: 2026-02-28 | R40: 2026-03-03T09:00:00+07:00 | S40: 2026-03-03T09:00:00+07:00
...

Sheet CSAT_Rekap
A1: csat_summary_id | B1: unit_code | C1: product_code | D1: area_code | E1: period_start | F1: period_end | G1: survey_version | H1: invited_count | I1: received_count | J1: valid_response_count | K1: excluded_count | L1: satisfied_count | M1: csat_ratio | N1: target_csat_ratio | O1: avg_product_score | P1: response_rate | Q1: sample_status | R1: reporting_status | S1: collected_at | T1: data_as_of_at
A2: CSAT-1-PROD-MILK | B2: UNIT-CS | C2: PROD-MILK | D2: AREA-A | E2: 2026-01-01 | F2: 2026-01-31 | G2: CSAT-5-V1 | H2: 100 | I2: =COUNTIFS('Survey_Data'!D:D,C2,'Survey_Data'!E:E,D2,'Survey_Data'!F:F,G2,'Survey_Data'!P:P,E2,'Survey_Data'!Q:Q,F2) -> 12 | J2: =SUMIFS('Survey_Data'!M:M,'Survey_Data'!D:D,C2,'Survey_Data'!E:E,D2,'Survey_Data'!F:F,G2,'Survey_Data'!P:P,E2,'Survey_Data'!Q:Q,F2) -> 11 | K2: =I2-J2 -> 1 | L2: =SUMIFS('Survey_Data'!N:N,'Survey_Data'!D:D,C2,'Survey_Data'!E:E,D2,'Survey_Data'!F:F,G2,'Survey_Data'!P:P,E2,'Survey_Data'!Q:Q,F2) -> 5 | M2: =IF(J2>0,L2/J2,"") -> 0.454545 | N2: 0.8 | O2: =AVERAGEIFS('Survey_Data'!H:H,'Survey_Data'!D:D,C2,'Survey_Data'!E:E,D2,'Survey_Data'!F:F,G2,'Survey_Data'!P:P,E2,'Survey_Data'!Q:Q,F2,'Survey_Data'!K:K,TRUE) -> 3.363636 | P2: =IF(H2>0,I2/H2,"") -> 0.12 | Q2: SMALL_OPT_IN_SAMPLE | R2: FINAL_SIMULATED | S2: 2026-03-03T09:00:00+07:00 | T2: 2026-03-03T09:00:00+07:00
A3: CSAT-1-PROD-FEED | B3: UNIT-CS | C3: PROD-FEED | D3: AREA-A | E3: 2026-01-01 | F3: 2026-01-31 | G3: CSAT-5-V1 | H3: 100 | I3: =COUNTIFS('Survey_Data'!D:D,C3,'Survey_Data'!E:E,D3,'Survey_Data'!F:F,G3,'Survey_Data'!P:P,E3,'Survey_Data'!Q:Q,F3) -> 12 | J3: =SUMIFS('Survey_Data'!M:M,'Survey_Data'!D:D,C3,'Survey_Data'!E:E,D3,'Survey_Data'!F:F,G3,'Survey_Data'!P:P,E3,'Survey_Data'!Q:Q,F3) -> 11 | K3: =I3-J3 -> 1 | L3: =SUMIFS('Survey_Data'!N:N,'Survey_Data'!D:D,C3,'Survey_Data'!E:E,D3,'Survey_Data'!F:F,G3,'Survey_Data'!P:P,E3,'Survey_Data'!Q:Q,F3) -> 5 | M3: =IF(J3>0,L3/J3,"") -> 0.454545 | N3: 0.8 | O3: =AVERAGEIFS('Survey_Data'!H:H,'Survey_Data'!D:D,C3,'Survey_Data'!E:E,D3,'Survey_Data'!F:F,G3,'Survey_Data'!P:P,E3,'Survey_Data'!Q:Q,F3,'Survey_Data'!K:K,TRUE) -> 3.363636 | P3: =IF(H3>0,I3/H3,"") -> 0.12 | Q3: SMALL_OPT_IN_SAMPLE | R3: FINAL_SIMULATED | S3: 2026-03-03T09:00:00+07:00 | T3: 2026-03-03T09:00:00+07:00
A4: CSAT-2-PROD-MILK | B4: UNIT-CS | C4: PROD-MILK | D4: AREA-A | E4: 2026-02-01 | F4: 2026-02-28 | G4: CSAT-5-V1 | H4: 100 | I4: =COUNTIFS('Survey_Data'!D:D,C4,'Survey_Data'!E:E,D4,'Survey_Data'!F:F,G4,'Survey_Data'!P:P,E4,'Survey_Data'!Q:Q,F4) -> 12 | J4: =SUMIFS('Survey_Data'!M:M,'Survey_Data'!D:D,C4,'Survey_Data'!E:E,D4,'Survey_Data'!F:F,G4,'Survey_Data'!P:P,E4,'Survey_Data'!Q:Q,F4) -> 11 | K4: =I4-J4 -> 1 | L4: =SUMIFS('Survey_Data'!N:N,'Survey_Data'!D:D,C4,'Survey_Data'!E:E,D4,'Survey_Data'!F:F,G4,'Survey_Data'!P:P,E4,'Survey_Data'!Q:Q,F4) -> 9 | M4: =IF(J4>0,L4/J4,"") -> 0.818182 | N4: 0.8 | O4: =AVERAGEIFS('Survey_Data'!H:H,'Survey_Data'!D:D,C4,'Survey_Data'!E:E,D4,'Survey_Data'!F:F,G4,'Survey_Data'!P:P,E4,'Survey_Data'!Q:Q,F4,'Survey_Data'!K:K,TRUE) -> 4.090909 | P4: =IF(H4>0,I4/H4,"") -> 0.12 | Q4: SMALL_OPT_IN_SAMPLE | R4: FINAL_SIMULATED | S4: 2026-03-03T09:00:00+07:00 | T4: 2026-03-03T09:00:00+07:00
A5: CSAT-2-PROD-FEED | B5: UNIT-CS | C5: PROD-FEED | D5: AREA-A | E5: 2026-02-01 | F5: 2026-02-28 | G5: CSAT-5-V1 | H5: 100 | I5: =COUNTIFS('Survey_Data'!D:D,C5,'Survey_Data'!E:E,D5,'Survey_Data'!F:F,G5,'Survey_Data'!P:P,E5,'Survey_Data'!Q:Q,F5) -> 12 | J5: =SUMIFS('Survey_Data'!M:M,'Survey_Data'!D:D,C5,'Survey_Data'!E:E,D5,'Survey_Data'!F:F,G5,'Survey_Data'!P:P,E5,'Survey_Data'!Q:Q,F5) -> 11 | K5: =I5-J5 -> 1 | L5: =SUMIFS('Survey_Data'!N:N,'Survey_Data'!D:D,C5,'Survey_Data'!E:E,D5,'Survey_Data'!F:F,G5,'Survey_Data'!P:P,E5,'Survey_Data'!Q:Q,F5) -> 9 | M5: =IF(J5>0,L5/J5,"") -> 0.818182 | N5: 0.8 | O5: =AVERAGEIFS('Survey_Data'!H:H,'Survey_Data'!D:D,C5,'Survey_Data'!E:E,D5,'Survey_Data'!F:F,G5,'Survey_Data'!P:P,E5,'Survey_Data'!Q:Q,F5,'Survey_Data'!K:K,TRUE) -> 4.090909 | P5: =IF(H5>0,I5/H5,"") -> 0.12 | Q5: SMALL_OPT_IN_SAMPLE | R5: FINAL_SIMULATED | S5: 2026-03-03T09:00:00+07:00 | T5: 2026-03-03T09:00:00+07:00

Sheet Action_Plan
A1: action_id | B1: source_sheet | C1: source_record_id | D1: unit_code | E1: indicator_code | F1: period_start | G1: period_end | H1: baseline_value | I1: target_value | J1: measurement_unit | K1: finding | L1: cause_hypothesis | M1: cause_status | N1: evidence_ref | O1: action_description | P1: owner_team_code | Q1: due_date | R1: action_status | S1: followup_start | T1: followup_end | U1: followup_value | V1: verification_status | W1: collected_at
A2: ACT-CSAT-01 | B2: CSAT_Rekap | C2: CSAT-1-PROD-MILK | D2: UNIT-CS | E2: PRODUCT_CSAT | F2: 2026-01-01 | G2: 2026-01-31 | H2: 0.454545 | I2: 0.8 | J2: RATIO | K2: CSAT produk Januari di bawah target contoh 80%. | L2: Masalah pengalaman produk masih dugaan; sampel kecil/self-selection dapat memengaruhi hasil. | M2: UNVERIFIED | N2: SIMULASI::CSAT_Rekap::CSAT-1-PROD-MILK | O2: Perbaiki cakupan sampel dan lakukan wawancara terstruktur anonim; verifikasi tema masalah sebelum uji perbaikan produk. | P2: TEAM-CS | Q2: 2026-02-15 | R2: PLANNED | S2: 2026-02-01 | T2: 2026-02-28 | V2: NOT_EVALUATED | W2: 2026-02-02T09:00:00+07:00
